Exception in thread SockSrvRdThr:
Traceback (most recent call last):
  File "/home/ray/anaconda3/lib/python3.11/threading.py", line 1045, in _bootstrap_inner
    self.run()
  File "/home/ray/anaconda3/lib/python3.11/site-packages/wandb/sdk/service/server_sock.py", line 99, in run
    sreq = self._sock_client.read_server_request()
           ^^^^^^^^^^^^^^^^^^^^^^^^^^^^^^^^^^^^^^^
  File "/home/ray/anaconda3/lib/python3.11/site-packages/wandb/sdk/lib/sock_client.py", line 274, in read_server_request
    data = self._read_packet_bytes()
           ^^^^^^^^^^^^^^^^^^^^^^^^^
  File "/home/ray/anaconda3/lib/python3.11/site-packages/wandb/sdk/lib/sock_client.py", line 248, in _read_packet_bytes
    rec = self._extract_packet_bytes()
          ^^^^^^^^^^^^^^^^^^^^^^^^^^^^
  File "/home/ray/anaconda3/lib/python3.11/site-packages/wandb/sdk/lib/sock_client.py", line 230, in _extract_packet_bytes
    assert magic == ord("W")
           ^^^^^^^^^^^^^^^^^
